Traceback (most recent call last):
  File "/opt/hostedtoolcache/Python/3.13.3/x64/lib/python3.13/site-packages/jupyter_core/utils/__init__.py", line 154, in wrapped
    asyncio.get_running_loop()
    ~~~~~~~~~~~~~~~~~~~~~~~~^^
RuntimeError: no running event loop

During handling of the above exception, another exception occurred:

Traceback (most recent call last):
  File "/opt/hostedtoolcache/Python/3.13.3/x64/lib/python3.13/site-packages/jupyter_cache/executors/utils.py", line 58, in single_nb_execution
    executenb(
    ~~~~~~~~~^
        nb,
        ^^^
    ...<4 lines>...
        **kwargs,
        ^^^^^^^^^
    )
    ^
  File "/opt/hostedtoolcache/Python/3.13.3/x64/lib/python3.13/site-packages/nbclient/client.py", line 1319, in execute
    return NotebookClient(nb=nb, resources=resources, km=km, **kwargs).execute()
           ~~~~~~~~~~~~~~~~~~~~~~~~~~~~~~~~~~~~~~~~~~~~~~~~~~~~~~~~~~~~~~~~~~~^^
  File "/opt/hostedtoolcache/Python/3.13.3/x64/lib/python3.13/site-packages/jupyter_core/utils/__init__.py", line 158, in wrapped
    return loop.run_until_complete(inner)
           ~~~~~~~~~~~~~~~~~~~~~~~^^^^^^^
  File "/opt/hostedtoolcache/Python/3.13.3/x64/lib/python3.13/asyncio/base_events.py", line 719, in run_until_complete
    return future.result()
           ~~~~~~~~~~~~~^^
  File "/opt/hostedtoolcache/Python/3.13.3/x64/lib/python3.13/site-packages/nbclient/client.py", line 709, in async_execute
    await self.async_execute_cell(
        cell, index, execution_count=self.code_cells_executed + 1
    )
  File "/opt/hostedtoolcache/Python/3.13.3/x64/lib/python3.13/site-packages/nbclient/client.py", line 1062, in async_execute_cell
    await self._check_raise_for_error(cell, cell_index, exec_reply)
  File "/opt/hostedtoolcache/Python/3.13.3/x64/lib/python3.13/site-packages/nbclient/client.py", line 918, in _check_raise_for_error
    raise CellExecutionError.from_cell_and_msg(cell, exec_reply_content)
nbclient.exceptions.CellExecutionError: An error occurred while executing the following cell:
------------------
internet_df["Date"] = pd.to_datetime(internet_df["Date"])
economic_df["Date"] = pd.to_datetime(economic_df["Date"])
internet_df["Year"] = internet_df["Date"].dt.year
economic_df["Year"] = economic_df["Date"].dt.year


internet_growth = internet_df.groupby(["Country", "Year"])["Internet_Penetration (%)"].mean().reset_index()
pivot_growth = internet_growth.pivot(index="Country", columns="Year", values="Internet_Penetration (%)")
pivot_growth = pivot_growth.dropna(subset=[2010, 2023])
pivot_growth["Growth (%)"] = pivot_growth[2023] - pivot_growth[2010]
growth_df = pivot_growth[["Growth (%)"]].reset_index()


unemployment = economic_df[(economic_df["Year"] >= 2010) & (economic_df["Year"] <= 2023)]
unemployment = unemployment.groupby(["Country"])["Unemployment Rate (%)"].mean().reset_index()


merged = pd.merge(unemployment, growth_df, on="Country", how="inner")

corr = merged["Growth (%)"].corr(merged["Unemployment Rate (%)"])
print(f"Correlatie digitale groei versus werkloosheid: {corr:.3f}")


threshold = merged["Growth (%)"].quantile(0.75)
fast_countries = sorted(merged[merged["Growth (%)"] >= threshold]["Country"].unique())
slow_countries = sorted(merged[merged["Growth (%)"] < threshold]["Country"].unique())


fast_label = "Snelle digitale groei: " + ", ".join(fast_countries)
slow_label = "Lage tot gemiddelde groei: " + ", ".join(slow_countries)


def label_groep(x):
    return fast_label if x >= threshold else slow_label


merged["Legend Label"] = merged["Growth (%)"].apply(label_groep)



grouped_bar = merged.groupby("Legend Label")["Unemployment Rate (%)"].mean().reset_index()


fig = px.bar(
    grouped_bar,
    x="Legend Label",
    y="Unemployment Rate (%)",
    color="Legend Label",
    title="Gemiddelde werkloosheid per groeigroep (2010â€“2023)",
    labels={
        "Unemployment Rate (%)": "Gemiddelde werkloosheid (%)",
        "Legend Label": "Digitale groeigroep + landen"
    },
)


fig.show()
------------------


[31m---------------------------------------------------------------------------[39m
[31mNameError[39m                                 Traceback (most recent call last)
[36mCell[39m[36m [39m[32mIn[8][39m[32m, line 2[39m
[32m      1[39m internet_df[[33m"[39m[33mDate[39m[33m"[39m] = pd.to_datetime(internet_df[[33m"[39m[33mDate[39m[33m"[39m])
[32m----> [39m[32m2[39m economic_df[[33m"[39m[33mDate[39m[33m"[39m] = pd.to_datetime([43meconomic_df[49m[[33m"[39m[33mDate[39m[33m"[39m])
[32m      3[39m internet_df[[33m"[39m[33mYear[39m[33m"[39m] = internet_df[[33m"[39m[33mDate[39m[33m"[39m].dt.year
[32m      4[39m economic_df[[33m"[39m[33mYear[39m[33m"[39m] = economic_df[[33m"[39m[33mDate[39m[33m"[39m].dt.year

[31mNameError[39m: name 'economic_df' is not defined

